2022-04-15 15:08:00,688 ERROR libqtile core.py:get_interesting_pid():L810 Got an exception in getting the window pid
Traceback (most recent call last):
  File "/usr/lib/python3.10/site-packages/xcffib/__init__.py", line 571, in wrapper
    return f(*args)
  File "/usr/lib/python3.10/site-packages/xcffib/__init__.py", line 658, in wait_for_reply
    self._process_error(error_p[0])
  File "/usr/lib/python3.10/site-packages/xcffib/__init__.py", line 645, in _process_error
    self.invalid()
  File "/usr/lib/python3.10/site-packages/xcffib/__init__.py", line 559, in invalid
    raise ConnectionException(err)
xcffib.ConnectionException: xcb connection errors because of socket, pipe and other stream errors.

During handling of the above exception, another exception occurred:

Traceback (most recent call last):
  File "/usr/lib/python3.10/site-packages/libqtile/backend/x11/core.py", line 808, in get_interesting_pid
    return win.window.get_net_wm_pid()
  File "/usr/lib/python3.10/site-packages/libqtile/backend/x11/window.py", line 293, in get_net_wm_pid
    r = self.get_property("_NET_WM_PID", unpack=int)
  File "/usr/lib/python3.10/site-packages/libqtile/backend/x11/window.py", line 381, in get_property
    ).reply()
  File "/usr/lib/python3.10/site-packages/xcffib/__init__.py", line 332, in reply
    data = self.conn.wait_for_reply(self.sequence)
  File "/usr/lib/python3.10/site-packages/xcffib/__init__.py", line 573, in wrapper
    self.invalid()
  File "/usr/lib/python3.10/site-packages/xcffib/__init__.py", line 559, in invalid
    raise ConnectionException(err)
xcffib.ConnectionException: xcb connection errors because of socket, pipe and other stream errors.
2022-04-15 15:08:00,790 ERROR libqtile manager.py:_finalize_configurables():L295 exception during finalize
Traceback (most recent call last):
  File "/usr/lib/python3.10/site-packages/libqtile/core/manager.py", line 283, in _finalize_configurables
    widget.finalize()
  File "/usr/lib/python3.10/site-packages/libqtile/widget/base.py", line 240, in finalize
    self.drawer.finalize()
  File "/usr/lib/python3.10/site-packages/libqtile/backend/x11/drawer.py", line 35, in finalize
    self._free_pixmap()
  File "/usr/lib/python3.10/site-packages/libqtile/backend/x11/drawer.py", line 115, in _free_pixmap
    self.qtile.core.conn.conn.core.FreePixmap(self._pixmap)
  File "/usr/lib/python3.10/site-packages/xcffib/xproto.py", line 2863, in FreePixmap
    return self.send_request(54, buf, is_checked=is_checked)
  File "/usr/lib/python3.10/site-packages/xcffib/__init__.py", line 391, in send_request
    seq = self.conn.send_request(flags, xcb_parts + 2, xcb_req)
  File "/usr/lib/python3.10/site-packages/xcffib/__init__.py", line 569, in wrapper
    self.invalid()
  File "/usr/lib/python3.10/site-packages/xcffib/__init__.py", line 559, in invalid
    raise ConnectionException(err)
xcffib.ConnectionException: xcb connection errors because of socket, pipe and other stream errors.
2022-04-15 15:08:00,791 ERROR libqtile core.py:_xpoll():L327 Shutting down due to X connection error XCB_CONN_ERROR (1)
Traceback (most recent call last):
  File "/usr/lib/python3.10/site-packages/libqtile/backend/x11/core.py", line 289, in _xpoll
    event = self.conn.conn.poll_for_event()
  File "/usr/lib/python3.10/site-packages/xcffib/__init__.py", line 569, in wrapper
    self.invalid()
  File "/usr/lib/python3.10/site-packages/xcffib/__init__.py", line 559, in invalid
    raise ConnectionException(err)
xcffib.ConnectionException: xcb connection errors because of socket, pipe and other stream errors.
2022-04-15 15:08:00,791 ERROR libqtile core.py:get_interesting_pid():L810 Got an exception in getting the window pid
Traceback (most recent call last):
  File "/usr/lib/python3.10/site-packages/libqtile/backend/x11/core.py", line 289, in _xpoll
    event = self.conn.conn.poll_for_event()
  File "/usr/lib/python3.10/site-packages/xcffib/__init__.py", line 569, in wrapper
    self.invalid()
  File "/usr/lib/python3.10/site-packages/xcffib/__init__.py", line 559, in invalid
    raise ConnectionException(err)
xcffib.ConnectionException: xcb connection errors because of socket, pipe and other stream errors.

During handling of the above exception, another exception occurred:

Traceback (most recent call last):
  File "/usr/lib/python3.10/site-packages/libqtile/backend/x11/core.py", line 808, in get_interesting_pid
    return win.window.get_net_wm_pid()
  File "/usr/lib/python3.10/site-packages/libqtile/backend/x11/window.py", line 293, in get_net_wm_pid
    r = self.get_property("_NET_WM_PID", unpack=int)
  File "/usr/lib/python3.10/site-packages/libqtile/backend/x11/window.py", line 374, in get_property
    r = self.conn.conn.core.GetProperty(
  File "/usr/lib/python3.10/site-packages/xcffib/xproto.py", line 2720, in GetProperty
    return self.send_request(20, buf, GetPropertyCookie, is_checked=is_checked)
  File "/usr/lib/python3.10/site-packages/xcffib/__init__.py", line 391, in send_request
    seq = self.conn.send_request(flags, xcb_parts + 2, xcb_req)
  File "/usr/lib/python3.10/site-packages/xcffib/__init__.py", line 569, in wrapper
    self.invalid()
  File "/usr/lib/python3.10/site-packages/xcffib/__init__.py", line 559, in invalid
    raise ConnectionException(err)
xcffib.ConnectionException: xcb connection errors because of socket, pipe and other stream errors.
2022-04-15 15:08:00,791 ERROR libqtile core.py:get_interesting_pid():L810 Got an exception in getting the window pid
Traceback (most recent call last):
  File "/usr/lib/python3.10/site-packages/libqtile/backend/x11/core.py", line 289, in _xpoll
    event = self.conn.conn.poll_for_event()
  File "/usr/lib/python3.10/site-packages/xcffib/__init__.py", line 569, in wrapper
    self.invalid()
  File "/usr/lib/python3.10/site-packages/xcffib/__init__.py", line 559, in invalid
    raise ConnectionException(err)
xcffib.ConnectionException: xcb connection errors because of socket, pipe and other stream errors.

During handling of the above exception, another exception occurred:

Traceback (most recent call last):
  File "/usr/lib/python3.10/site-packages/libqtile/backend/x11/core.py", line 808, in get_interesting_pid
    return win.window.get_net_wm_pid()
  File "/usr/lib/python3.10/site-packages/libqtile/backend/x11/window.py", line 293, in get_net_wm_pid
    r = self.get_property("_NET_WM_PID", unpack=int)
  File "/usr/lib/python3.10/site-packages/libqtile/backend/x11/window.py", line 374, in get_property
    r = self.conn.conn.core.GetProperty(
  File "/usr/lib/python3.10/site-packages/xcffib/xproto.py", line 2720, in GetProperty
    return self.send_request(20, buf, GetPropertyCookie, is_checked=is_checked)
  File "/usr/lib/python3.10/site-packages/xcffib/__init__.py", line 391, in send_request
    seq = self.conn.send_request(flags, xcb_parts + 2, xcb_req)
  File "/usr/lib/python3.10/site-packages/xcffib/__init__.py", line 569, in wrapper
    self.invalid()
  File "/usr/lib/python3.10/site-packages/xcffib/__init__.py", line 559, in invalid
    raise ConnectionException(err)
xcffib.ConnectionException: xcb connection errors because of socket, pipe and other stream errors.
2022-04-15 15:08:00,791 ERROR libqtile core.py:get_interesting_pid():L810 Got an exception in getting the window pid
Traceback (most recent call last):
  File "/usr/lib/python3.10/site-packages/libqtile/backend/x11/core.py", line 808, in get_interesting_pid
    return win.window.get_net_wm_pid()
  File "/usr/lib/python3.10/site-packages/libqtile/backend/x11/window.py", line 293, in get_net_wm_pid
    r = self.get_property("_NET_WM_PID", unpack=int)
  File "/usr/lib/python3.10/site-packages/libqtile/backend/x11/window.py", line 374, in get_property
    r = self.conn.conn.core.GetProperty(
  File "/usr/lib/python3.10/site-packages/xcffib/xproto.py", line 2720, in GetProperty
    return self.send_request(20, buf, GetPropertyCookie, is_checked=is_checked)
  File "/usr/lib/python3.10/site-packages/xcffib/__init__.py", line 391, in send_request
    seq = self.conn.send_request(flags, xcb_parts + 2, xcb_req)
  File "/usr/lib/python3.10/site-packages/xcffib/__init__.py", line 569, in wrapper
    self.invalid()
  File "/usr/lib/python3.10/site-packages/xcffib/__init__.py", line 559, in invalid
    raise ConnectionException(err)
xcffib.ConnectionException: xcb connection errors because of socket, pipe and other stream errors.
2022-04-15 15:08:00,791 ERROR libqtile core.py:get_interesting_pid():L810 Got an exception in getting the window pid
Traceback (most recent call last):
  File "/usr/lib/python3.10/site-packages/libqtile/backend/x11/core.py", line 808, in get_interesting_pid
    return win.window.get_net_wm_pid()
  File "/usr/lib/python3.10/site-packages/libqtile/backend/x11/window.py", line 293, in get_net_wm_pid
    r = self.get_property("_NET_WM_PID", unpack=int)
  File "/usr/lib/python3.10/site-packages/libqtile/backend/x11/window.py", line 374, in get_property
    r = self.conn.conn.core.GetProperty(
  File "/usr/lib/python3.10/site-packages/xcffib/xproto.py", line 2720, in GetProperty
    return self.send_request(20, buf, GetPropertyCookie, is_checked=is_checked)
  File "/usr/lib/python3.10/site-packages/xcffib/__init__.py", line 391, in send_request
    seq = self.conn.send_request(flags, xcb_parts + 2, xcb_req)
  File "/usr/lib/python3.10/site-packages/xcffib/__init__.py", line 569, in wrapper
    self.invalid()
  File "/usr/lib/python3.10/site-packages/xcffib/__init__.py", line 559, in invalid
    raise ConnectionException(err)
xcffib.ConnectionException: xcb connection errors because of socket, pipe and other stream errors.
2022-04-15 15:08:00,792 ERROR libqtile start.py:start():L94 Qtile crashed
Traceback (most recent call last):
  File "/usr/lib/python3.10/site-packages/libqtile/scripts/start.py", line 92, in start
    q.loop()
  File "/usr/lib/python3.10/site-packages/libqtile/core/manager.py", line 192, in loop
    asyncio.run(self.async_loop())
  File "/usr/lib/python3.10/asyncio/runners.py", line 44, in run
    return loop.run_until_complete(main)
  File "/usr/lib/python3.10/asyncio/base_events.py", line 646, in run_until_complete
    return future.result()
  File "/usr/lib/python3.10/site-packages/libqtile/core/manager.py", line 220, in async_loop
    self.finalize()
  File "/usr/lib/python3.10/site-packages/libqtile/core/manager.py", line 300, in finalize
    self.core.finalize()
  File "/usr/lib/python3.10/site-packages/libqtile/backend/x11/core.py", line 165, in finalize
    self.conn.conn.core.DeletePropertyChecked(
  File "/usr/lib/python3.10/site-packages/xcffib/xproto.py", line 2716, in DeleteProperty
    return self.send_request(19, buf, is_checked=is_checked)
  File "/usr/lib/python3.10/site-packages/xcffib/__init__.py", line 391, in send_request
    seq = self.conn.send_request(flags, xcb_parts + 2, xcb_req)
  File "/usr/lib/python3.10/site-packages/xcffib/__init__.py", line 569, in wrapper
    self.invalid()
  File "/usr/lib/python3.10/site-packages/xcffib/__init__.py", line 559, in invalid
    raise ConnectionException(err)
xcffib.ConnectionException: xcb connection errors because of socket, pipe and other stream errors.
2022-04-15 15:08:00,793 WARNING libqtile lifecycle.py:_atexit():L37 Qtile will now terminate
2022-04-15 15:10:05,644 WARNING libqtile utils.py:send_notification():L246 dbus-next is not installed. Unable to send notifications.
2022-04-15 15:12:08,105 ERROR libqtile manager.py:cmd_reload_config():L260 Configuration error: 'color5'
2022-04-15 15:12:08,105 WARNING libqtile utils.py:send_notification():L246 dbus-next is not installed. Unable to send notifications.
2022-04-15 15:12:09,564 ERROR libqtile manager.py:cmd_reload_config():L260 Configuration error: 'color5'
2022-04-15 15:12:09,564 WARNING libqtile utils.py:send_notification():L246 dbus-next is not installed. Unable to send notifications.
2022-04-15 15:12:09,997 ERROR libqtile manager.py:cmd_reload_config():L260 Configuration error: 'color5'
2022-04-15 15:12:09,997 WARNING libqtile utils.py:send_notification():L246 dbus-next is not installed. Unable to send notifications.
2022-04-15 15:12:11,111 WARNING libqtile lifecycle.py:_atexit():L37 Qtile will now terminate
2022-04-15 15:12:22,171 WARNING libqtile utils.py:send_notification():L246 dbus-next is not installed. Unable to send notifications.
2022-04-15 15:12:47,458 ERROR libqtile manager.py:cmd_reload_config():L260 Configuration error: cannot import name 'widget_defaults' from 'settings.widgets' (/home/jesus/.config/qtile/settings/widgets.py)
2022-04-15 15:12:47,458 WARNING libqtile utils.py:send_notification():L246 dbus-next is not installed. Unable to send notifications.
2022-04-15 15:12:48,712 ERROR libqtile manager.py:cmd_reload_config():L260 Configuration error: cannot import name 'widget_defaults' from 'settings.widgets' (/home/jesus/.config/qtile/settings/widgets.py)
2022-04-15 15:12:48,712 WARNING libqtile utils.py:send_notification():L246 dbus-next is not installed. Unable to send notifications.
2022-04-15 15:12:49,016 ERROR libqtile manager.py:cmd_reload_config():L260 Configuration error: cannot import name 'widget_defaults' from 'settings.widgets' (/home/jesus/.config/qtile/settings/widgets.py)
2022-04-15 15:12:49,016 WARNING libqtile utils.py:send_notification():L246 dbus-next is not installed. Unable to send notifications.
2022-04-15 15:12:49,220 ERROR libqtile manager.py:cmd_reload_config():L260 Configuration error: cannot import name 'widget_defaults' from 'settings.widgets' (/home/jesus/.config/qtile/settings/widgets.py)
2022-04-15 15:12:49,220 WARNING libqtile utils.py:send_notification():L246 dbus-next is not installed. Unable to send notifications.
2022-04-15 15:12:50,491 ERROR libqtile manager.py:cmd_reload_config():L260 Configuration error: cannot import name 'widget_defaults' from 'settings.widgets' (/home/jesus/.config/qtile/settings/widgets.py)
2022-04-15 15:12:50,491 WARNING libqtile utils.py:send_notification():L246 dbus-next is not installed. Unable to send notifications.
2022-04-15 15:12:59,982 ERROR libqtile manager.py:cmd_reload_config():L260 Configuration error: cannot import name 'widget_defaults' from 'settings.widgets' (/home/jesus/.config/qtile/settings/widgets.py)
2022-04-15 15:12:59,982 WARNING libqtile utils.py:send_notification():L246 dbus-next is not installed. Unable to send notifications.
2022-04-15 15:13:03,042 ERROR libqtile manager.py:cmd_reload_config():L260 Configuration error: cannot import name 'widget_defaults' from 'settings.widgets' (/home/jesus/.config/qtile/settings/widgets.py)
2022-04-15 15:13:03,042 WARNING libqtile utils.py:send_notification():L246 dbus-next is not installed. Unable to send notifications.
2022-04-15 15:13:22,863 ERROR libqtile manager.py:cmd_reload_config():L260 Configuration error: cannot import name 'widget_defaults' from 'settings.widgets' (/home/jesus/.config/qtile/settings/widgets.py)
2022-04-15 15:13:22,863 WARNING libqtile utils.py:send_notification():L246 dbus-next is not installed. Unable to send notifications.
2022-04-15 15:13:33,024 ERROR libqtile manager.py:cmd_reload_config():L260 Configuration error: cannot import name 'widget_defaults' from 'settings.widgets' (/home/jesus/.config/qtile/settings/widgets.py)
2022-04-15 15:13:33,024 WARNING libqtile utils.py:send_notification():L246 dbus-next is not installed. Unable to send notifications.
2022-04-15 15:13:34,209 WARNING libqtile lifecycle.py:_atexit():L37 Qtile will now terminate
